Workbook

Sheet Contents
A1: This workbook supplements CBO’s report How Changes in Economic Conditions Might Affect the Federal Budget: 2025 to 2035.
A2: www.cbo.gov/publication/61198
A5: Contents
A7: 1. Interactive Table: How Changes in Productivity Growth Might Affect the Federal Budget
A8: 2. Interactive Table: How Changes in Labor Force Growth Might Affect the Federal Budget
A9: 3. Interactive Table: How Changes in Interest Rates Might Affect the Federal Budget
A10: 4. Interactive Table: How Changes in Inflation and Interest Rates Might Affect the Federal Budget
A11: 5. Illustrative Scenario: How Productivity Growth That Was 0.1 Percentage Point Slower Each Year Than It Is in CBO’s Forecast Might Aﬀect the Federal Budget
A12: 6. Illustrative Scenario: How Labor Force Growth That Was 0.1 Percentage Point Slower Each Year Than It Is in CBO’s Forecast Might Aﬀect the Federal Budget
A13: 7. Illustrative Scenario: How Interest Rates That Were 0.1 Percentage Point Higher Each Year Than They Are in CBO’s Forecast Might Aﬀect the Federal Budget
A14: 8. Illustrative Scenario: How Inflation and Interest Rates That Were 0.1 Percentage Point Higher Each Year Than They Are in CBO’s Forecast Might Aﬀect the Federal Budget
A17: About This Workbook
... A29: Because the scalability of the rules of thumb is limited, only moderate changes in economic variables in this workbook will produce reasonable approximations of the estimates that CBO’s broader set of models would produce. To determine the limits of the workbook, CBO ran simulations using several values for year-by-year differences for each of the four variables. The agency found that the workbook produced plausible estimates when differences in productivity growth ranged from −0.5 percentage points to 0.5 percentage points, differences in labor force growth ranged from −0.75 percentage points to 0.75 percentage points, and differences in interest rates and inflation ranged from −1.0 percentage point to 1.0 percentage point. Any scenario with differences outside those ranges cannot be analyzed with this workbook and would require a more detailed analysis.

Sheet 1. Productivity
A1: This workbook supplements CBO’s report How Changes in Economic Conditions Might Affect the Federal Budget: 2025 to 2035.
A2: www.cbo.gov/publication/61198
A5: To create an alternative scenario for productivity growth, enter values between -0.5 percentage points and 0.5 percentage points in each of the green cells. (Only the green cells can be edited; all other cells are locked. Values outside of the specified range will produce errors.) The change in budgetary outcomes relative to those in CBO’s baseline will be calculated and appear automatically. Values for key economic indicators are shown below those budgetary effects.
A7: 1. Interactive Table: How Changes in Productivity Growth Might Affect the Federal Budget
B9: 2024 | C9: 2025 | D9: 2026 | E9: 2027 | F9: 2028 | G9: 2029 | H9: 2030 | I9: 2031 | J9: 2032 | K9: 2033 | L9: 2034 | M9: 2035
C11: User-specified scenario for annual productivity growth
O12: These initial values are the same as those used to generate the illustrative scenario shown in Worksheet 5, “Productivity_CBO.”
A13: Increase or decrease (-) in productivity growth relative to CBO’s January 2025 baseline (percentage points) | B13: n.a. | C13: 0 | D13: 0.1 | E13: 0.2 | F13: 0.3 | G13: 0.4 | H13: 0.5 | I13: 0.5 | J13: 0.5 | K13: 0.5 | L13: 0.5 | M13: 0.5
A14: =IF($A$19,"Please keep values in the range [-0.5, 0.5] percentage points per year.","")
A15: Productivity growth (percent)a
A16: January 2025 baseline | B16: 0.98 | C16: 0.983 | D16: 1.015 | E16: 1.058 | F16: 1.105 | G16: 1.129 | H16: 1.126 | I16: 1.125 | J16: 1.121 | K16: 1.116 | L16: 1.114 | M16: 1.112
A17: User-specified scenario | B17: =IF($A$19,"n.a.",B16) -> 0.98 | C17: =IF($A$19,"n.a.",C16+C13) -> 0.983 | D17: =IF($A$19,"n.a.",D16+D13) -> 1.115 | E17: =IF($A$19,"n.a.",E16+E13) -> 1.258 | F17: =IF($A$19,"n.a.",F16+F13) -> 1.405 | G17: =IF($A$19,"n.a.",G16+G13) -> 1.529 | H17: =IF($A$19,"n.a.",H16+H13) -> 1.626 | I17: =IF($A$19,"n.a.",I16+I13) -> 1.625 | J17: =IF($A$19,"n.a.",J16+J13) -> 1.621 | ... M17: =IF($A$19,"n.a.",M16+M13) -> 1.612
A19: =IF(OR(MAX(C13:M13)>0.5,MIN(C13:M13)<-0.5),1,0) -> 0
C21: Budgetary effects (billions of dollars) | N21: Total
N22: 2026- | O22: 2026-
B23: 2024 | C23: 2025 | D23: 2026 | E23: 2027 | F23: 2028 | G23: 2029 | H23: 2030 | I23: 2031 | J23: 2032 | K23: 2033 | L23: 2034 | M23: 2035 | N23: 2030 | O23: 2035
A24: Changes in revenues | B24: n.a. | C24: =IF($A$19,"n.a.",ROUND('5. Productivity_CBO'!C11/('5. Productivity_CBO'!C57-'5. Productivity_CBO'!C56)*(ROUND('1. Productivity'!C70,1)-ROUND('1. Productivity'!C69,1)),3)) -> 0 | D24: =IF($A$19,"n.a.",ROUND('5. Productivity_CBO'!D11/('5. Productivity_CBO'!D57-'5. Productivity_CBO'!D56)*(ROUND('1. Productivity'!D70,1)-ROUND('1. Productivity'!D69,1)),3)) -> 4.692 | E24: =IF($A$19,"n.a.",ROUND('5. Productivity_CBO'!E11/('5. Productivity_CBO'!E57-'5. Productivity_CBO'!E56)*(ROUND('1. Productivity'!E70,1)-ROUND('1. Productivity'!E69,1)),3)) -> 16.899 | F24: =IF($A$19,"n.a.",ROUND('5. Productivity_CBO'!F11/('5. Productivity_CBO'!F57-'5. Productivity_CBO'!F56)*(ROUND('1. Productivity'!F70,1)-ROUND('1. Productivity'!F69,1)),3)) -> 37.689 | G24: =IF($A$19,"n.a.",ROUND('5. Productivity_CBO'!G11/('5. Productivity_CBO'!G57-'5. Productivity_CBO'!G56)*(ROUND('1. Productivity'!G70,1)-ROUND('1. Productivity'!G69,1)),3)) -> 68.355 | H24: =IF($A$19,"n.a.",ROUND('5. Productivity_CBO'!H11/('5. Productivity_CBO'!H57-'5. Productivity_CBO'!H56)*(ROUND('1. Productivity'!H70,1)-ROUND('1. Productivity'!H69,1)),3)) -> 110.403 | I24: =IF($A$19,"n.a.",ROUND('5. Productivity_CBO'!I11/('5. Productivity_CBO'!I57-'5. Productivity_CBO'!I56)*(ROUND('1. Productivity'!I70,1)-ROUND('1. Productivity'!I69,1)),3)) -> 159.169 | J24: =IF($A$19,"n.a.",ROUND('5. Productivity_CBO'!J11/('5. Productivity_CBO'!J57-'5. Productivity_CBO'!J56)*(ROUND('1. Productivity'!J70,1)-ROUND('1. Productivity'!J69,1)),3)) -> 213.498 | ... M24: =IF($A$19,"n.a.",ROUND('5. Productivity_CBO'!M11/('5. Productivity_CBO'!M57-'5. Productivity_CBO'!M56)*(ROUND('1. Productivity'!M70,1)-ROUND('1. Productivity'!M69,1)),3)) -> 411.038 | N24: =IF($A$19,"n.a.",SUM(D24:H24)) -> 238.038 | O24: =IF($A$19,"n.a.",SUM(D24:M24)) -> 1633.737
A26: Changes in outlays
A27: Mandatory outlays | B27: n.a. | C27: =IF($A$19,"n.a.",ROUND('5. Productivity_CBO'!C14/('5. Productivity_CBO'!C57-'5. Productivity_CBO'!C56)*(ROUND('1. Productivity'!C70,1)-ROUND('1. Productivity'!C69,1)),3)) -> 0 | D27: =IF($A$19,"n.a.",ROUND('5. Productivity_CBO'!D14/('5. Productivity_CBO'!D57-'5. Productivity_CBO'!D56)*(ROUND('1. Productivity'!D70,1)-ROUND('1. Productivity'!D69,1)),3)) -> 0.207 | E27: =IF($A$19,"n.a.",ROUND('5. Productivity_CBO'!E14/('5. Productivity_CBO'!E57-'5. Productivity_CBO'!E56)*(ROUND('1. Productivity'!E70,1)-ROUND('1. Productivity'!E69,1)),3)) -> 0.949 | F27: =IF($A$19,"n.a.",ROUND('5. Productivity_CBO'!F14/('5. Productivity_CBO'!F57-'5. Productivity_CBO'!F56)*(ROUND('1. Productivity'!F70,1)-ROUND('1. Productivity'!F69,1)),3)) -> 2.604 | G27: =IF($A$19,"n.a.",ROUND('5. Productivity_CBO'!G14/('5. Productivity_CBO'!G57-'5. Productivity_CBO'!G56)*(ROUND('1. Productivity'!G70,1)-ROUND('1. Productivity'!G69,1)),3)) -> 4.579 | H27: =IF($A$19,"n.a.",ROUND('5. Productivity_CBO'!H14/('5. Productivity_CBO'!H57-'5. Productivity_CBO'!H56)*(ROUND('1. Productivity'!H70,1)-ROUND('1. Productivity'!H69,1)),3)) -> 7.712 | I27: =IF($A$19,"n.a.",ROUND('5. Productivity_CBO'!I14/('5. Productivity_CBO'!I57-'5. Productivity_CBO'!I56)*(ROUND('1. Productivity'!I70,1)-ROUND('1. Productivity'!I69,1)),3)) -> 11.444 | J27: =IF($A$19,"n.a.",ROUND('5. Productivity_CBO'!J14/('5. Productivity_CBO'!J57-'5. Productivity_CBO'!J56)*(ROUND('1. Productivity'!J70,1)-ROUND('1. Productivity'!J69,1)),3)) -> 15.949 | ... M27: =IF($A$19,"n.a.",ROUND('5. Productivity_CBO'!M14/('5. Productivity_CBO'!M57-'5. Productivity_CBO'!M56)*(ROUND('1. Productivity'!M70,1)-ROUND('1. Productivity'!M69,1)),3)) -> 34.417 | N27: =IF($A$19,"n.a.",SUM(D27:H27)) -> 16.051 | O27: =IF($A$19,"n.a.",SUM(D27:M27)) -> 126.708
A28: Discretionary outlaysb | B28: n.a. | C28: =IF($A$19,"n.a.",0) -> 0 | D28: =IF($A$19,"n.a.",0) -> 0 | E28: =IF($A$19,"n.a.",0) -> 0 | F28: =IF($A$19,"n.a.",0) -> 0 | G28: =IF($A$19,"n.a.",0) -> 0 | H28: =IF($A$19,"n.a.",0) -> 0 | I28: =IF($A$19,"n.a.",0) -> 0 | J28: =IF($A$19,"n.a.",0) -> 0 | ... M28: =IF($A$19,"n.a.",0) -> 0 | N28: =IF($A$19,"n.a.",SUM(D28:H28)) -> 0 | O28: =IF($A$19,"n.a.",SUM(D28:M28)) -> 0
A29: Net interest outlays
A30: Effects from changes in interest rates | B30: n.a. | C30: {=IF($A$19,"n.a.",ROUND(SUMPRODUCT(TRANSPOSE($C117:$M117),C119:C129),3)+ROUND(C131*C117/('5. Productivity_CBO'!C63-'5. Productivity_CBO'!C62),3))} -> 0 | D30: {=IF($A$19,"n.a.",ROUND(SUMPRODUCT(TRANSPOSE($C117:$M117),D119:D129),3)+ROUND(D131*D117/('5. Productivity_CBO'!D63-'5. Productivity_CBO'!D62),3))} -> 0.723 | E30: {=IF($A$19,"n.a.",ROUND(SUMPRODUCT(TRANSPOSE($C117:$M117),E119:E129),3)+ROUND(E131*E117/('5. Productivity_CBO'!E63-'5. Productivity_CBO'!E62),3))} -> 3.246 | F30: {=IF($A$19,"n.a.",ROUND(SUMPRODUCT(TRANSPOSE($C117:$M117),F119:F129),3)+ROUND(F131*F117/('5. Productivity_CBO'!F63-'5. Productivity_CBO'!F62),3))} -> 8.33 | G30: {=IF($A$19,"n.a.",ROUND(SUMPRODUCT(TRANSPOSE($C117:$M117),G119:G129),3)+ROUND(G131*G117/('5. Productivity_CBO'!G63-'5. Productivity_CBO'!G62),3))} -> 16.642 | H30: {=IF($A$19,"n.a.",ROUND(SUMPRODUCT(TRANSPOSE($C117:$M117),H119:H129),3)+ROUND(H131*H117/('5. Productivity_CBO'!H63-'5. Productivity_CBO'!H62),3))} -> 29.165 | I30: {=IF($A$19,"n.a.",ROUND(SUMPRODUCT(TRANSPOSE($C117:$M117),I119:I129),3)+ROUND(I131*I117/('5. Productivity_CBO'!I63-'5. Productivity_CBO'!I62),3))} -> 45.488 | J30: {=IF($A$19,"n.a.",ROUND(SUMPRODUCT(TRANSPOSE($C117:$M117),J119:J129),3)+ROUND(J131*J117/('5. Productivity_CBO'!J63-'5. Productivity_CBO'!J62),3))} -> 65.076 | ... M30: {=IF($A$19,"n.a.",ROUND(SUMPRODUCT(TRANSPOSE($C117:$M117),M119:M129),3)+ROUND(M131*M117/('5. Productivity_CBO'!M63-'5. Productivity_CBO'!M62),3))} -> 138.07 | N30: =IF($A$19,"n.a.",SUM(D30:H30)) -> 58.106 | O30: =IF($A$19,"n.a.",SUM(D30:M30)) -> 505.16
A31: Debt service | B31: n.a. | C31: {=IF($A$19,"n.a.",ROUND(SUMPRODUCT($C133:$M133,TRANSPOSE(C135:C145)),3) + ROUND(C147*(-C133)/('5. Productivity_CBO'!C24+'5. Productivity_CBO'!C18),3))} -> 0 | D31: {=IF($A$19,"n.a.",ROUND(SUMPRODUCT($C133:$M133,TRANSPOSE(D135:D145)),3) + ROUND(D147*(-D133)/('5. Productivity_CBO'!D24+'5. Productivity_CBO'!D18),3))} -> -0.069 | E31: {=IF($A$19,"n.a.",ROUND(SUMPRODUCT($C133:$M133,TRANSPOSE(E135:E145)),3) + ROUND(E147*(-E133)/('5. Productivity_CBO'!E24+'5. Productivity_CBO'!E18),3))} -> -0.366 | F31: {=IF($A$19,"n.a.",ROUND(SUMPRODUCT($C133:$M133,TRANSPOSE(F135:F145)),3) + ROUND(F147*(-F133)/('5. Productivity_CBO'!F24+'5. Productivity_CBO'!F18),3))} -> -1.065 | G31: {=IF($A$19,"n.a.",ROUND(SUMPRODUCT($C133:$M133,TRANSPOSE(G135:G145)),3) + ROUND(G147*(-G133)/('5. Productivity_CBO'!G24+'5. Productivity_CBO'!G18),3))} -> -2.367 | H31: {=IF($A$19,"n.a.",ROUND(SUMPRODUCT($C133:$M133,TRANSPOSE(H135:H145)),3) + ROUND(H147*(-H133)/('5. Productivity_CBO'!H24+'5. Productivity_CBO'!H18),3))} -> -4.479 | I31: {=IF($A$19,"n.a.",ROUND(SUMPRODUCT($C133:$M133,TRANSPOSE(I135:I145)),3) + ROUND(I147*(-I133)/('5. Productivity_CBO'!I24+'5. Productivity_CBO'!I18),3))} -> -7.535 | J31: {=IF($A$19,"n.a.",ROUND(SUMPRODUCT($C133:$M133,TRANSPOSE(J135:J145)),3) + ROUND(J147*(-J133)/('5. Productivity_CBO'!J24+'5. Productivity_CBO'!J18),3))} -> -11.643 | ... M31: {=IF($A$19,"n.a.",ROUND(SUMPRODUCT($C133:$M133,TRANSPOSE(M135:M145)),3) + ROUND(M147*(-M133)/('5. Productivity_CBO'!M24+'5. Productivity_CBO'!M18),3))} -> -31.032 | N31: =IF($A$19,"n.a.",SUM(D31:H31)) -> -8.346 | O31: =IF($A$19,"n.a.",SUM(D31:M31)) -> -98.724
B32: ____ | C32: ____ | D32: ____ | E32: ____ | F32: ____ | G32: ____ | H32: ____ | I32: ____ | J32: ____ | K32: ____ | L32: ____ | M32: ____ | N32: ____ | O32: ____
A33: Subtotal, net interest outlays | B33: n.a. | C33: =IF($A$19,"n.a.",C30+C31) -> 0 | D33: =IF($A$19,"n.a.",D30+D31) -> 0.654 | E33: =IF($A$19,"n.a.",E30+E31) -> 2.88 | F33: =IF($A$19,"n.a.",F30+F31) -> 7.265 | G33: =IF($A$19,"n.a.",G30+G31) -> 14.275 | H33: =IF($A$19,"n.a.",H30+H31) -> 24.686 | I33: =IF($A$19,"n.a.",I30+I31) -> 37.953 | J33: =IF($A$19,"n.a.",J30+J31) -> 53.433 | ... M33: =IF($A$19,"n.a.",M30+M31) -> 107.038 | N33: =IF($A$19,"n.a.",SUM(D33:H33)) -> 49.76 | O33: =IF($A$19,"n.a.",SUM(D33:M33)) -> 406.436
A35: Total change in outlays | B35: n.a. | C35: =IF($A$19,"n.a.",C27+C28+C33) -> 0 | D35: =IF($A$19,"n.a.",D27+D28+D33) -> 0.861 | E35: =IF($A$19,"n.a.",E27+E28+E33) -> 3.829 | F35: =IF($A$19,"n.a.",F27+F28+F33) -> 9.869 | G35: =IF($A$19,"n.a.",G27+G28+G33) -> 18.854 | H35: =IF($A$19,"n.a.",H27+H28+H33) -> 32.398 | I35: =IF($A$19,"n.a.",I27+I28+I33) -> 49.397 | J35: =IF($A$19,"n.a.",J27+J28+J33) -> 69.382 | ... M35: =IF($A$19,"n.a.",M27+M28+M33) -> 141.455 | N35: =IF($A$19,"n.a.",SUM(D35:H35)) -> 65.811 | O35: =IF($A$19,"n.a.",SUM(D35:M35)) -> 533.144
A37: Increase (-) or decrease in the deficit relative to CBO’s baseline | B37: n.a. | C37: =IF($A$19,"n.a.",C24-C35) -> 0 | D37: =IF($A$19,"n.a.",D24-D35) -> 3.831 | E37: =IF($A$19,"n.a.",E24-E35) -> 13.07 | F37: =IF($A$19,"n.a.",F24-F35) -> 27.82 | G37: =IF($A$19,"n.a.",G24-G35) -> 49.501 | H37: =IF($A$19,"n.a.",H24-H35) -> 78.005 | I37: =IF($A$19,"n.a.",I24-I35) -> 109.772 | J37: =IF($A$19,"n.a.",J24-J35) -> 144.116 | ... M37: =IF($A$19,"n.a.",M24-M35) -> 269.583 | N37: =IF($A$19,"n.a.",SUM(D37:H37)) -> 172.227 | O37: =IF($A$19,"n.a.",SUM(D37:M37)) -> 1100.593
A39: Deficit (-) or surplus
A40: January 2025 baseline | B40: -1832.381 | C40: -1865.251 | D40: -1713.258 | E40: -1686.942 | F40: -1910.776 | G40: -1938.268 | H40: -2139.721 | I40: -2232.786 | J40: -2370.582 | K40: -2637.299 | L40: -2597.25 | M40: -2531.378 | N40: -9388.965 | O40: -21758.26
A41: User-specified scenario | B41: =IF($A$19,"n.a.",B40) -> -1832.381 | C41: =IF($A$19,"n.a.",C40+C37) -> -1865.251 | D41: =IF($A$19,"n.a.",D40+D37) -> -1709.427 | E41: =IF($A$19,"n.a.",E40+E37) -> -1673.872 | F41: =IF($A$19,"n.a.",F40+F37) -> -1882.956 | G41: =IF($A$19,"n.a.",G40+G37) -> -1888.767 | H41: =IF($A$19,"n.a.",H40+H37) -> -2061.716 | I41: =IF($A$19,"n.a.",I40+I37) -> -2123.014 | J41: =IF($A$19,"n.a.",J40+J37) -> -2226.466 | ... M41: =IF($A$19,"n.a.",M40+M37) -> -2261.795 | N41: =IF($A$19,"n.a.",SUM(D41:H41)) -> -9216.738 | O41: =IF($A$19,"n.a.",SUM(D41:M41)) -> -20657.667
A43: Debt held by the public
A44: January 2025 baseline | B44: 28199.313 | C44: 30102.749 | D44: 31882.633 | E44: 33636.105 | F44: 35600.64 | G44: 37580.5 | H44: 39747.651 | I44: 41992.385 | J44: 44371.755 | K44: 46985.029 | L44: 49555.504 | M44: 52055.866 | N44: n.a. | O44: n.a.
A45: User-specified scenario | B45: =IF($A$19,"n.a.",B44) -> 28199.313 | C45: =IF($A$19,"n.a.",C44-SUM($C37:C37)) -> 30102.749 | D45: =IF($A$19,"n.a.",D44-SUM($C37:D37)) -> 31878.802 | E45: =IF($A$19,"n.a.",E44-SUM($C37:E37)) -> 33619.204 | F45: =IF($A$19,"n.a.",F44-SUM($C37:F37)) -> 35555.919 | G45: =IF($A$19,"n.a.",G44-SUM($C37:G37)) -> 37486.278 | H45: =IF($A$19,"n.a.",H44-SUM($C37:H37)) -> 39575.424 | I45: =IF($A$19,"n.a.",I44-SUM($C37:I37)) -> 41710.386 | J45: =IF($A$19,"n.a.",J44-SUM($C37:J37)) -> 43945.64 | ... M45: =IF($A$19,"n.a.",M44-SUM($C37:M37)) -> 50955.273 | N45: n.a. | O45: n.a.
A47: Deficit (-) or surplus (percentage of GDP)
A48: January 2025 baseline | B48: -6.3562158 | C48: -6.1894147 | D48: -5.4664504 | E48: -5.184518 | F48: -5.659123 | G48: -5.5304586 | H48: -5.8793652 | I48: -5.9080768 | J48: -6.0393242 | K48: -6.4690633 | L48: -6.1356563 | M48: -5.7614482 | N48: -5.5528141 | O48: -5.830748
A49: User-specified scenario | B49: =IF($A$19,"n.a.",B48) -> -6.3562158 | C49: =IF($A$19,"n.a.",ROUND(C41/C70*100,3)) -> -6.189 | D49: =IF($A$19,"n.a.",ROUND(D41/D70*100,3)) -> -5.45 | E49: =IF($A$19,"n.a.",ROUND(E41/E70*100,3)) -> -5.13 | F49: =IF($A$19,"n.a.",ROUND(F41/F70*100,3)) -> -5.544 | G49: =IF($A$19,"n.a.",ROUND(G41/G70*100,3)) -> -5.335 | H49: =IF($A$19,"n.a.",ROUND(H41/H70*100,3)) -> -5.577 | I49: =IF($A$19,"n.a.",ROUND(I41/I70*100,3)) -> -5.498 | J49: =IF($A$19,"n.a.",ROUND(J41/J70*100,3)) -> -5.518 | ... M49: =IF($A$19,"n.a.",ROUND(M41/M70*100,3)) -> -4.913 | N49: =IF($A$19,"n.a.",ROUND(SUM(D41:H41)/SUM(D70:H70)*100,3)) -> -5.411 | O49: =IF($A$19,"n.a.",ROUND(SUM(D41:M41)/SUM(D70:M70)*100,3)) -> -5.414
A51: Debt held by the public (percentage of GDP)
A52: January 2025 baseline | B52: 97.818585 | C52: 99.889183 | D52: 101.72714 | E52: 103.37462 | F52: 105.438 | G52: 107.22841 | H52: 109.21562 | I52: 111.1142 | J52: 113.04204 | K52: 115.25016 | L52: 117.06826 | M52: 118.47981 | N52: n.a. | O52: n.a.
A53: User-specified scenario | B53: =IF($A$19,"n.a.",B52) -> 97.818585 | C53: =IF($A$19,"n.a.",ROUND(C45/C70*100,3)) -> 99.889 | D53: =IF($A$19,"n.a.",ROUND(D45/D70*100,3)) -> 101.631 | E53: =IF($A$19,"n.a.",ROUND(E45/E70*100,3)) -> 103.038 | F53: =IF($A$19,"n.a.",ROUND(F45/F70*100,3)) -> 104.693 | G53: =IF($A$19,"n.a.",ROUND(G45/G70*100,3)) -> 105.885 | H53: =IF($A$19,"n.a.",ROUND(H45/H70*100,3)) -> 107.062 | I53: =IF($A$19,"n.a.",ROUND(I45/I70*100,3)) -> 108.024 | J53: =IF($A$19,"n.a.",ROUND(J45/J70*100,3)) -> 108.916 | ... M53: =IF($A$19,"n.a.",ROUND(M45/M70*100,3)) -> 110.693 | N53: n.a. | O53: n.a.
B56: Economic indicators in CBO’s January 2025 baseline and under the user-specified scenario
...

Sheet 2. Labor Force
A1: This workbook supplements CBO’s report How Changes in Economic Conditions Might Affect the Federal Budget: 2025 to 2035.
A2: www.cbo.gov/publication/61198
A5: To create an alternative scenario for labor force growth, enter values between -0.75 percentage points and 0.75 percentage points in each of the green cells. (Only the green cells can be edited; all other cells are locked. Values outside of the specified range will produce errors.) The change in budgetary outcomes relative to those in CBO’s baseline will be calculated and appear automatically. Values for key economic indicators are shown below those budgetary effects.
A7: 2. Interactive Table: How Changes in Labor Force Growth Might Affect the Federal Budget
B9: 2024 | C9: 2025 | D9: 2026 | E9: 2027 | F9: 2028 | G9: 2029 | H9: 2030 | I9: 2031 | J9: 2032 | K9: 2033 | L9: 2034 | M9: 2035
C11: User-specified scenario for annual labor force growth
O12: These initial values are the same as those used to generate the illustrative scenario shown in Worksheet 6, “Labor Force_CBO.”
A13: Increase or decrease (-) in labor force growth relative to CBO’s January 2025 baseline (percentage points) | B13: n.a. | C13: -0.1 | D13: -0.1 | E13: -0.1 | F13: -0.1 | G13: -0.1 | H13: -0.1 | I13: -0.1 | J13: -0.1 | K13: -0.1 | L13: -0.1 | M13: -0.1
A14: =IF($A$19,"Please keep values in the range [-0.75, 0.75] percentage points per year.","")
A15: Labor force growth (percent)
A16: January 2025 baseline | B16: 0.67 | C16: 1.438 | D16: 1.589 | E16: 0.364 | F16: 0.349 | G16: 0.389 | H16: 0.419 | I16: 0.437 | J16: 0.428 | K16: 0.348 | L16: 0.347 | M16: 0.33
A17: User-specified scenarioa | B17: =IF($A$19,"n.a.",B16) -> 0.67 | C17: =IF($A$19,"n.a.",(C73/B73-1)*100) -> 1.3444839 | D17: =IF($A$19,"n.a.",(D73/C73-1)*100) -> 1.4955573 | E17: =IF($A$19,"n.a.",(E73/D73-1)*100) -> 0.26927855 | F17: =IF($A$19,"n.a.",(F73/E73-1)*100) -> 0.25472421 | G17: =IF($A$19,"n.a.",(G73/F73-1)*100) -> 0.29546513 | H17: =IF($A$19,"n.a.",(H73/G73-1)*100) -> 0.32439806 | I17: =IF($A$19,"n.a.",(I73/H73-1)*100) -> 0.34277292 | J17: =IF($A$19,"n.a.",(J73/I73-1)*100) -> 0.33306195 | ... M17: =IF($A$19,"n.a.",(M73/L73-1)*100) -> 0.23543493
A19: =IF(OR(MAX(C13:M13)>0.75,MIN(C13:M13)<-0.75),1,0) -> 0
C21: Budgetary effects (billions of dollars) | N21: Total
N22: 2026- | O22: 2026-
B23: 2024 | C23: 2025 | D23: 2026 | E23: 2027 | F23: 2028 | G23: 2029 | H23: 2030 | I23: 2031 | J23: 2032 | K23: 2033 | L23: 2034 | M23: 2035 | N23: 2030 | O23: 2035
A24: Changes in revenues | B24: n.a. | C24: =IF($A$19,"n.a.",ROUND('6. Labor Force_CBO'!C11/('6. Labor Force_CBO'!C57-'6. Labor Force_CBO'!C56)*(ROUND('2. Labor Force'!C70,1)-ROUND('2. Labor Force'!C69,1)),3)) -> -1.649 | D24: =IF($A$19,"n.a.",ROUND('6. Labor Force_CBO'!D11/('6. Labor Force_CBO'!D57-'6. Labor Force_CBO'!D56)*(ROUND('2. Labor Force'!D70,1)-ROUND('2. Labor Force'!D69,1)),3)) -> -4.283 | E24: =IF($A$19,"n.a.",ROUND('6. Labor Force_CBO'!E11/('6. Labor Force_CBO'!E57-'6. Labor Force_CBO'!E56)*(ROUND('2. Labor Force'!E70,1)-ROUND('2. Labor Force'!E69,1)),3)) -> -7.2 | F24: =IF($A$19,"n.a.",ROUND('6. Labor Force_CBO'!F11/('6. Labor Force_CBO'!F57-'6. Labor Force_CBO'!F56)*(ROUND('2. Labor Force'!F70,1)-ROUND('2. Labor Force'!F69,1)),3)) -> -10.373 | G24: =IF($A$19,"n.a.",ROUND('6. Labor Force_CBO'!G11/('6. Labor Force_CBO'!G57-'6. Labor Force_CBO'!G56)*(ROUND('2. Labor Force'!G70,1)-ROUND('2. Labor Force'!G69,1)),3)) -> -13.878 | H24: =IF($A$19,"n.a.",ROUND('6. Labor Force_CBO'!H11/('6. Labor Force_CBO'!H57-'6. Labor Force_CBO'!H56)*(ROUND('2. Labor Force'!H70,1)-ROUND('2. Labor Force'!H69,1)),3)) -> -17.782 | I24: =IF($A$19,"n.a.",ROUND('6. Labor Force_CBO'!I11/('6. Labor Force_CBO'!I57-'6. Labor Force_CBO'!I56)*(ROUND('2. Labor Force'!I70,1)-ROUND('2. Labor Force'!I69,1)),3)) -> -22.053 | J24: =IF($A$19,"n.a.",ROUND('6. Labor Force_CBO'!J11/('6. Labor Force_CBO'!J57-'6. Labor Force_CBO'!J56)*(ROUND('2. Labor Force'!J70,1)-ROUND('2. Labor Force'!J69,1)),3)) -> -26.788 | ... M24: =IF($A$19,"n.a.",ROUND('6. Labor Force_CBO'!M11/('6. Labor Force_CBO'!M57-'6. Labor Force_CBO'!M56)*(ROUND('2. Labor Force'!M70,1)-ROUND('2. Labor Force'!M69,1)),3)) -> -43.764 | N24: =IF($A$19,"n.a.",SUM(D24:H24)) -> -53.516 | O24: =IF($A$19,"n.a.",SUM(D24:M24)) -> -215.642
A26: Changes in outlays
A27: Mandatory outlays | B27: n.a. | C27: =IF($A$19,"n.a.",ROUND('6. Labor Force_CBO'!C14/('6. Labor Force_CBO'!C57-'6. Labor Force_CBO'!C56)*(ROUND('2. Labor Force'!C70,1)-ROUND('2. Labor Force'!C69,1)),3)) -> 0.281 | D27: =IF($A$19,"n.a.",ROUND('6. Labor Force_CBO'!D14/('6. Labor Force_CBO'!D57-'6. Labor Force_CBO'!D56)*(ROUND('2. Labor Force'!D70,1)-ROUND('2. Labor Force'!D69,1)),3)) -> 0.74 | E27: =IF($A$19,"n.a.",ROUND('6. Labor Force_CBO'!E14/('6. Labor Force_CBO'!E57-'6. Labor Force_CBO'!E56)*(ROUND('2. Labor Force'!E70,1)-ROUND('2. Labor Force'!E69,1)),3)) -> 1.211 | F27: =IF($A$19,"n.a.",ROUND('6. Labor Force_CBO'!F14/('6. Labor Force_CBO'!F57-'6. Labor Force_CBO'!F56)*(ROUND('2. Labor Force'!F70,1)-ROUND('2. Labor Force'!F69,1)),3)) -> 1.733 | G27: =IF($A$19,"n.a.",ROUND('6. Labor Force_CBO'!G14/('6. Labor Force_CBO'!G57-'6. Labor Force_CBO'!G56)*(ROUND('2. Labor Force'!G70,1)-ROUND('2. Labor Force'!G69,1)),3)) -> 2.29 | H27: =IF($A$19,"n.a.",ROUND('6. Labor Force_CBO'!H14/('6. Labor Force_CBO'!H57-'6. Labor Force_CBO'!H56)*(ROUND('2. Labor Force'!H70,1)-ROUND('2. Labor Force'!H69,1)),3)) -> 2.856 | I27: =IF($A$19,"n.a.",ROUND('6. Labor Force_CBO'!I14/('6. Labor Force_CBO'!I57-'6. Labor Force_CBO'!I56)*(ROUND('2. Labor Force'!I70,1)-ROUND('2. Labor Force'!I69,1)),3)) -> 3.532 | J27: =IF($A$19,"n.a.",ROUND('6. Labor Force_CBO'!J14/('6. Labor Force_CBO'!J57-'6. Labor Force_CBO'!J56)*(ROUND('2. Labor Force'!J70,1)-ROUND('2. Labor Force'!J69,1)),3)) -> 4.482 | ... M27: =IF($A$19,"n.a.",ROUND('6. Labor Force_CBO'!M14/('6. Labor Force_CBO'!M57-'6. Labor Force_CBO'!M56)*(ROUND('2. Labor Force'!M70,1)-ROUND('2. Labor Force'!M69,1)),3)) -> 7.304 | N27: =IF($A$19,"n.a.",SUM(D27:H27)) -> 8.83 | O27: =IF($A$19,"n.a.",SUM(D27:M27)) -> 35.906
A28: Discretionary outlaysb | B28: n.a. | C28: =IF($A$19,"n.a.",0) -> 0 | D28: =IF($A$19,"n.a.",0) -> 0 | E28: =IF($A$19,"n.a.",0) -> 0 | F28: =IF($A$19,"n.a.",0) -> 0 | G28: =IF($A$19,"n.a.",0) -> 0 | H28: =IF($A$19,"n.a.",0) -> 0 | I28: =IF($A$19,"n.a.",0) -> 0 | J28: =IF($A$19,"n.a.",0) -> 0 | ... M28: =IF($A$19,"n.a.",0) -> 0 | N28: =IF($A$19,"n.a.",SUM(D28:H28)) -> 0 | O28: =IF($A$19,"n.a.",SUM(D28:M28)) -> 0
A29: Net interest outlays
A30: Effects from changes in interest rates | B30: n.a. | C30: {=IF($A$19,"n.a.",ROUND(SUMPRODUCT(TRANSPOSE($C115:$M115),C117:C127),3)+ROUND(C129*C115/('6. Labor Force_CBO'!C63-'6. Labor Force_CBO'!C62),3))} -> -0.3 | D30: {=IF($A$19,"n.a.",ROUND(SUMPRODUCT(TRANSPOSE($C115:$M115),D117:D127),3)+ROUND(D129*D115/('6. Labor Force_CBO'!D63-'6. Labor Force_CBO'!D62),3))} -> -1.101 | E30: {=IF($A$19,"n.a.",ROUND(SUMPRODUCT(TRANSPOSE($C115:$M115),E117:E127),3)+ROUND(E129*E115/('6. Labor Force_CBO'!E63-'6. Labor Force_CBO'!E62),3))} -> -2.174 | F30: {=IF($A$19,"n.a.",ROUND(SUMPRODUCT(TRANSPOSE($C115:$M115),F117:F127),3)+ROUND(F129*F115/('6. Labor Force_CBO'!F63-'6. Labor Force_CBO'!F62),3))} -> -3.507 | G30: {=IF($A$19,"n.a.",ROUND(SUMPRODUCT(TRANSPOSE($C115:$M115),G117:G127),3)+ROUND(G129*G115/('6. Labor Force_CBO'!G63-'6. Labor Force_CBO'!G62),3))} -> -5.131 | H30: {=IF($A$19,"n.a.",ROUND(SUMPRODUCT(TRANSPOSE($C115:$M115),H117:H127),3)+ROUND(H129*H115/('6. Labor Force_CBO'!H63-'6. Labor Force_CBO'!H62),3))} -> -7.009 | I30: {=IF($A$19,"n.a.",ROUND(SUMPRODUCT(TRANSPOSE($C115:$M115),I117:I127),3)+ROUND(I129*I115/('6. Labor Force_CBO'!I63-'6. Labor Force_CBO'!I62),3))} -> -9.071 | J30: {=IF($A$19,"n.a.",ROUND(SUMPRODUCT(TRANSPOSE($C115:$M115),J117:J127),3)+ROUND(J129*J115/('6. Labor Force_CBO'!J63-'6. Labor Force_CBO'!J62),3))} -> -11.442 | ... M30: {=IF($A$19,"n.a.",ROUND(SUMPRODUCT(TRANSPOSE($C115:$M115),M117:M127),3)+ROUND(M129*M115/('6. Labor Force_CBO'!M63-'6. Labor Force_CBO'!M62),3))} -> -19.399 | N30: =IF($A$19,"n.a.",SUM(D30:H30)) -> -18.922 | O30: =IF($A$19,"n.a.",SUM(D30:M30)) -> -89.358
A31: Debt service | B31: n.a. | C31: {=IF($A$19,"n.a.",ROUND(SUMPRODUCT($C131:$M131,TRANSPOSE(C133:C143)),3) + ROUND((-C145)*C131/('6. Labor Force_CBO'!C24+'6. Labor Force_CBO'!C18),3))} -> 0.017 | D31: {=IF($A$19,"n.a.",ROUND(SUMPRODUCT($C131:$M131,TRANSPOSE(D133:D143)),3) + ROUND((-D145)*D131/('6. Labor Force_CBO'!D24+'6. Labor Force_CBO'!D18),3))} -> 0.138 | E31: {=IF($A$19,"n.a.",ROUND(SUMPRODUCT($C131:$M131,TRANSPOSE(E133:E143)),3) + ROUND((-E145)*E131/('6. Labor Force_CBO'!E24+'6. Labor Force_CBO'!E18),3))} -> 0.329 | F31: {=IF($A$19,"n.a.",ROUND(SUMPRODUCT($C131:$M131,TRANSPOSE(F133:F143)),3) + ROUND((-F145)*F131/('6. Labor Force_CBO'!F24+'6. Labor Force_CBO'!F18),3))} -> 0.609 | G31: {=IF($A$19,"n.a.",ROUND(SUMPRODUCT($C131:$M131,TRANSPOSE(G133:G143)),3) + ROUND((-G145)*G131/('6. Labor Force_CBO'!G24+'6. Labor Force_CBO'!G18),3))} -> 0.982 | H31: {=IF($A$19,"n.a.",ROUND(SUMPRODUCT($C131:$M131,TRANSPOSE(H133:H143)),3) + ROUND((-H145)*H131/('6. Labor Force_CBO'!H24+'6. Labor Force_CBO'!H18),3))} -> 1.457 | I31: {=IF($A$19,"n.a.",ROUND(SUMPRODUCT($C131:$M131,TRANSPOSE(I133:I143)),3) + ROUND((-I145)*I131/('6. Labor Force_CBO'!I24+'6. Labor Force_CBO'!I18),3))} -> 2.036 | J31: {=IF($A$19,"n.a.",ROUND(SUMPRODUCT($C131:$M131,TRANSPOSE(J133:J143)),3) + ROUND((-J145)*J131/('6. Labor Force_CBO'!J24+'6. Labor Force_CBO'!J18),3))} -> 2.743 | ... M31: {=IF($A$19,"n.a.",ROUND(SUMPRODUCT($C131:$M131,TRANSPOSE(M133:M143)),3) + ROUND((-M145)*M131/('6. Labor Force_CBO'!M24+'6. Labor Force_CBO'!M18),3))} -> 5.776 | N31: =IF($A$19,"n.a.",SUM(D31:H31)) -> 3.515 | O31: =IF($A$19,"n.a.",SUM(D31:M31)) -> 22.254
B32: ____ | C32: ____ | D32: ____ | E32: ____ | F32: ____ | G32: ____ | H32: ____ | I32: ____ | J32: ____ | K32: ____ | L32: ____ | M32: ____ | N32: ____ | O32: ____
A33: Subtotal, net interest outlays | B33: n.a. | C33: =IF($A$19,"n.a.",C30+C31) -> -0.283 | D33: =IF($A$19,"n.a.",D30+D31) -> -0.963 | E33: =IF($A$19,"n.a.",E30+E31) -> -1.845 | F33: =IF($A$19,"n.a.",F30+F31) -> -2.898 | G33: =IF($A$19,"n.a.",G30+G31) -> -4.149 | H33: =IF($A$19,"n.a.",H30+H31) -> -5.552 | I33: =IF($A$19,"n.a.",I30+I31) -> -7.035 | J33: =IF($A$19,"n.a.",J30+J31) -> -8.699 | ... M33: =IF($A$19,"n.a.",M30+M31) -> -13.623 | N33: =IF($A$19,"n.a.",SUM(D33:H33)) -> -15.407 | O33: =IF($A$19,"n.a.",SUM(D33:M33)) -> -67.104
A35: Total change in outlays | B35: n.a. | C35: =IF($A$19,"n.a.",C27+C28+C33) -> -0.002 | D35: =IF($A$19,"n.a.",D27+D28+D33) -> -0.223 | E35: =IF($A$19,"n.a.",E27+E28+E33) -> -0.634 | F35: =IF($A$19,"n.a.",F27+F28+F33) -> -1.165 | G35: =IF($A$19,"n.a.",G27+G28+G33) -> -1.859 | H35: =IF($A$19,"n.a.",H27+H28+H33) -> -2.696 | I35: =IF($A$19,"n.a.",I27+I28+I33) -> -3.503 | J35: =IF($A$19,"n.a.",J27+J28+J33) -> -4.217 | ... M35: =IF($A$19,"n.a.",M27+M28+M33) -> -6.319 | N35: =IF($A$19,"n.a.",SUM(D35:H35)) -> -6.577 | O35: =IF($A$19,"n.a.",SUM(D35:M35)) -> -31.198
A37: Increase (-) or decrease in the deficit relative to CBO’s baseline | B37: n.a. | C37: =IF($A$19,"n.a.",C24-C35) -> -1.647 | D37: =IF($A$19,"n.a.",D24-D35) -> -4.06 | E37: =IF($A$19,"n.a.",E24-E35) -> -6.566 | F37: =IF($A$19,"n.a.",F24-F35) -> -9.208 | G37: =IF($A$19,"n.a.",G24-G35) -> -12.019 | H37: =IF($A$19,"n.a.",H24-H35) -> -15.086 | I37: =IF($A$19,"n.a.",I24-I35) -> -18.55 | J37: =IF($A$19,"n.a.",J24-J35) -> -22.571 | ... M37: =IF($A$19,"n.a.",M24-M35) -> -37.445 | N37: =IF($A$19,"n.a.",SUM(D37:H37)) -> -46.939 | O37: =IF($A$19,"n.a.",SUM(D37:M37)) -> -184.444
A39: Deficit (-) or surplus
A40: January 2025 baseline | B40: -1832.381 | C40: -1865.251 | D40: -1713.258 | E40: -1686.942 | F40: -1910.776 | G40: -1938.268 | H40: -2139.721 | I40: -2232.786 | J40: -2370.582 | K40: -2637.299 | L40: -2597.25 | M40: -2531.378 | N40: -9388.965 | O40: -21758.26
A41: User-specified scenario | B41: =IF($A$19,"n.a.",B40) -> -1832.381 | C41: =IF($A$19,"n.a.",C40+C37) -> -1866.898 | D41: =IF($A$19,"n.a.",D40+D37) -> -1717.318 | E41: =IF($A$19,"n.a.",E40+E37) -> -1693.508 | F41: =IF($A$19,"n.a.",F40+F37) -> -1919.984 | G41: =IF($A$19,"n.a.",G40+G37) -> -1950.287 | H41: =IF($A$19,"n.a.",H40+H37) -> -2154.807 | I41: =IF($A$19,"n.a.",I40+I37) -> -2251.336 | J41: =IF($A$19,"n.a.",J40+J37) -> -2393.153 | ... M41: =IF($A$19,"n.a.",M40+M37) -> -2568.823 | N41: =IF($A$19,"n.a.",SUM(D41:H41)) -> -9435.904 | O41: =IF($A$19,"n.a.",SUM(D41:M41)) -> -21942.704
A43: Debt held by the public
A44: January 2025 baseline | B44: 28199.313 | C44: 30102.749 | D44: 31882.633 | E44: 33636.105 | F44: 35600.64 | G44: 37580.5 | H44: 39747.651 | I44: 41992.385 | J44: 44371.755 | K44: 46985.029 | L44: 49555.504 | M44: 52055.866 | N44: n.a. | O44: n.a.
A45: User-specified scenario | B45: =IF($A$19,"n.a.",B44) -> 28199.313 | C45: =IF($A$19,"n.a.",C44-SUM($C37:C37)) -> 30104.396 | D45: =IF($A$19,"n.a.",D44-SUM($C37:D37)) -> 31888.34 | E45: =IF($A$19,"n.a.",E44-SUM($C37:E37)) -> 33648.378 | F45: =IF($A$19,"n.a.",F44-SUM($C37:F37)) -> 35622.121 | G45: =IF($A$19,"n.a.",G44-SUM($C37:G37)) -> 37614 | H45: =IF($A$19,"n.a.",H44-SUM($C37:H37)) -> 39796.237 | I45: =IF($A$19,"n.a.",I44-SUM($C37:I37)) -> 42059.521 | J45: =IF($A$19,"n.a.",J44-SUM($C37:J37)) -> 44461.462 | ... M45: =IF($A$19,"n.a.",M44-SUM($C37:M37)) -> 52241.957 | N45: n.a. | O45: n.a.
A47: Deficit (-) or surplus (percentage of GDP)
A48: January 2025 baseline | B48: -6.3562158 | C48: -6.1894147 | D48: -5.4664504 | E48: -5.184518 | F48: -5.659123 | G48: -5.5304586 | H48: -5.8793652 | I48: -5.9080768 | J48: -6.0393242 | K48: -6.4690633 | L48: -6.1356563 | M48: -5.7614482 | N48: -5.5528141 | O48: -5.830748
A49: User-specified scenario | B49: =IF($A$19,"n.a.",B48) -> -6.3562158 | C49: =IF($A$19,"n.a.",ROUND(C41/C70*100,3)) -> -6.197 | D49: =IF($A$19,"n.a.",ROUND(D41/D70*100,3)) -> -5.484 | E49: =IF($A$19,"n.a.",ROUND(E41/E70*100,3)) -> -5.212 | F49: =IF($A$19,"n.a.",ROUND(F41/F70*100,3)) -> -5.698 | G49: =IF($A$19,"n.a.",ROUND(G41/G70*100,3)) -> -5.579 | H49: =IF($A$19,"n.a.",ROUND(H41/H70*100,3)) -> -5.94 | I49: =IF($A$19,"n.a.",ROUND(I41/I70*100,3)) -> -5.98 | J49: =IF($A$19,"n.a.",ROUND(J41/J70*100,3)) -> -6.124 | ... M49: =IF($A$19,"n.a.",ROUND(M41/M70*100,3)) -> -5.885 | N49: =IF($A$19,"n.a.",ROUND(SUM(D41:H41)/SUM(D70:H70)*100,3)) -> -5.592 | O49: =IF($A$19,"n.a.",ROUND(SUM(D41:M41)/SUM(D70:M70)*100,3)) -> -5.903
A51: Debt held by the public (percentage of GDP)
A52: January 2025 baseline | B52: 97.818585 | C52: 99.889183 | D52: 101.72714 | E52: 103.37462 | F52: 105.438 | G52: 107.22841 | H52: 109.21562 | I52: 111.1142 | J52: 113.04204 | K52: 115.25016 | L52: 117.06826 | M52: 118.47981 | N52: n.a. | O52: n.a.
A53: User-specified scenario | B53: =IF($A$19,"n.a.",B52) -> 97.818585 | C53: =IF($A$19,"n.a.",ROUND(C45/C70*100,3)) -> 99.934 | D53: =IF($A$19,"n.a.",ROUND(D45/D70*100,3)) -> 101.839 | E53: =IF($A$19,"n.a.",ROUND(E45/E70*100,3)) -> 103.565 | F53: =IF($A$19,"n.a.",ROUND(F45/F70*100,3)) -> 105.719 | G53: =IF($A$19,"n.a.",ROUND(G45/G70*100,3)) -> 107.608 | H53: =IF($A$19,"n.a.",ROUND(H45/H70*100,3)) -> 109.705 | I53: =IF($A$19,"n.a.",ROUND(I45/I70*100,3)) -> 111.723 | J53: =IF($A$19,"n.a.",ROUND(J45/J70*100,3)) -> 113.782 | ... M53: =IF($A$19,"n.a.",ROUND(M45/M70*100,3)) -> 119.679 | N53: n.a. | O53: n.a.
B56: Economic indicators in CBO’s January 2025 baseline and under the user-specified scenario
...

Sheet 3. Interest Rates
A1: This workbook supplements CBO’s report How Changes in Economic Conditions Might Affect the Federal Budget: 2025 to 2035.
A2: www.cbo.gov/publication/61198
A5: To create an alternative scenario for interest rates, enter values between -1.0 percentage point and 1.0 percentage point in each of the green cells. (Only the green cells can be edited; all other cells are locked. Values outside of the specified range will produce errors.) The change in budgetary outcomes relative to those in CBO’s baseline will be calculated and appear automatically. Values for key economic indicators are shown below those budgetary effects.
A7: 3. Interactive Table: How Changes in Interest Rates Might Affect the Federal Budget
B9: 2024 | C9: 2025 | D9: 2026 | E9: 2027 | F9: 2028 | G9: 2029 | H9: 2030 | I9: 2031 | J9: 2032 | K9: 2033 | L9: 2034 | M9: 2035
C11: User-specified scenario for interest rates
O12: These initial values are the same as those used to generate the illustrative scenario shown in Worksheet 7, “Interest Rates_CBO.”
A13: Increase or decrease (-) in interest rates relative to CBO’s January 2025 baseline (percentage points) | B13: n.a. | C13: 0.1 | D13: 0.1 | E13: 0.1 | F13: 0.1 | G13: 0.1 | H13: 0.1 | I13: 0.1 | J13: 0.1 | K13: 0.1 | L13: 0.1 | M13: 0.1
A14: =IF($A$19,"Please keep values in the range [-1.0, 1.0] percentage point per year.","")
A15: Interest rate on 10-year Treasury notes (percent)a
A16: January 2025 baseline | B16: 4.188 | C16: 4.093 | D16: 3.935 | E16: 3.914 | F16: 3.894 | G16: 3.871 | H16: 3.85 | I16: 3.836 | J16: 3.826 | K16: 3.815 | L16: 3.797 | M16: 3.772
A17: User-specified scenario | B17: =IF($A$19,"n.a.",B16) -> 4.188 | C17: =IF($A$19,"n.a.",C16+C13) -> 4.193 | D17: =IF($A$19,"n.a.",D16+D13) -> 4.035 | E17: =IF($A$19,"n.a.",E16+E13) -> 4.014 | F17: =IF($A$19,"n.a.",F16+F13) -> 3.994 | G17: =IF($A$19,"n.a.",G16+G13) -> 3.971 | H17: =IF($A$19,"n.a.",H16+H13) -> 3.95 | I17: =IF($A$19,"n.a.",I16+I13) -> 3.936 | J17: =IF($A$19,"n.a.",J16+J13) -> 3.926 | ... M17: =IF($A$19,"n.a.",M16+M13) -> 3.872
A19: =IF(OR(MAX(C13:M13)>1,MIN(C13:M13)<-1),1,0) -> 0
C21: Budgetary effects (billions of dollars) | N21: Total
N22: 2026- | O22: 2026-
B23: 2024 | C23: 2025 | D23: 2026 | E23: 2027 | F23: 2028 | G23: 2029 | H23: 2030 | I23: 2031 | J23: 2032 | K23: 2033 | L23: 2034 | M23: 2035 | N23: 2030 | O23: 2035
A24: Changes in revenues | B24: n.a. | C24: {=IF($A$19,"n.a.",TRUNC(SUMPRODUCT($C13:$M13,TRANSPOSE(C108:C118))-C120*(C13*0.75),3))} -> -2.563 | D24: {=IF($A$19,"n.a.",TRUNC(SUMPRODUCT($C13:$M13,TRANSPOSE(D108:D118))-D120*(D13*0.75+C13*0.25),3))} -> -2.565 | E24: {=IF($A$19,"n.a.",TRUNC(SUMPRODUCT($C13:$M13,TRANSPOSE(E108:E118))-E120*(E13*0.75+D13*0.25),3))} -> -1.678 | F24: {=IF($A$19,"n.a.",TRUNC(SUMPRODUCT($C13:$M13,TRANSPOSE(F108:F118))-F120*(F13*0.75+E13*0.25),3))} -> -0.88 | G24: {=IF($A$19,"n.a.",TRUNC(SUMPRODUCT($C13:$M13,TRANSPOSE(G108:G118))-G120*(G13*0.75+F13*0.25),3))} -> -0.173 | H24: {=IF($A$19,"n.a.",TRUNC(SUMPRODUCT($C13:$M13,TRANSPOSE(H108:H118))-H120*(H13*0.75+G13*0.25),3))} -> 0.5 | I24: {=IF($A$19,"n.a.",TRUNC(SUMPRODUCT($C13:$M13,TRANSPOSE(I108:I118))-I120*(I13*0.75+H13*0.25),3))} -> 1.011 | J24: {=IF($A$19,"n.a.",TRUNC(SUMPRODUCT($C13:$M13,TRANSPOSE(J108:J118))-J120*(J13*0.75+I13*0.25),3))} -> 1.513 | K24: {=IF($A$19,"n.a.",TRUNC(SUMPRODUCT($C13:$M13,TRANSPOSE(K108:K118))-K120*(K13*0.75+J13*0.25),3))} -> 1.933 | ... M24: {=IF($A$19,"n.a.",TRUNC(SUMPRODUCT($C13:$M13,TRANSPOSE(M108:M118))-M120*(M13*0.75+L13*0.25),3))} -> 2.635 | N24: =IF($A$19,"n.a.",SUM(D24:H24)) -> -4.796 | O24: =IF($A$19,"n.a.",SUM(D24:M24)) -> 4.585
A26: Changes in outlays
A27: Mandatory outlays | B27: n.a. | C27: =IF($A$19,"n.a.",ROUND('7. Interest Rates_CBO'!C14*C122/('7. Interest Rates_CBO'!C63-'7. Interest Rates_CBO'!C62),3)) -> 0 | D27: =IF($A$19,"n.a.",ROUND('7. Interest Rates_CBO'!D14*D122/('7. Interest Rates_CBO'!D63-'7. Interest Rates_CBO'!D62),3)) -> 0 | E27: =IF($A$19,"n.a.",ROUND('7. Interest Rates_CBO'!E14*E122/('7. Interest Rates_CBO'!E63-'7. Interest Rates_CBO'!E62),3)) -> 0 | F27: =IF($A$19,"n.a.",ROUND('7. Interest Rates_CBO'!F14*F122/('7. Interest Rates_CBO'!F63-'7. Interest Rates_CBO'!F62),3)) -> 0 | G27: =IF($A$19,"n.a.",ROUND('7. Interest Rates_CBO'!G14*G122/('7. Interest Rates_CBO'!G63-'7. Interest Rates_CBO'!G62),3)) -> 0 | H27: =IF($A$19,"n.a.",ROUND('7. Interest Rates_CBO'!H14*H122/('7. Interest Rates_CBO'!H63-'7. Interest Rates_CBO'!H62),3)) -> 0 | I27: =IF($A$19,"n.a.",ROUND('7. Interest Rates_CBO'!I14*I122/('7. Interest Rates_CBO'!I63-'7. Interest Rates_CBO'!I62),3)) -> 0 | J27: =IF($A$19,"n.a.",ROUND('7. Interest Rates_CBO'!J14*J122/('7. Interest Rates_CBO'!J63-'7. Interest Rates_CBO'!J62),3)) -> 0 | ... M27: =IF($A$19,"n.a.",ROUND('7. Interest Rates_CBO'!M14*M122/('7. Interest Rates_CBO'!M63-'7. Interest Rates_CBO'!M62),3)) -> 0 | N27: =IF($A$19,"n.a.",SUM(D27:H27)) -> 0 | O27: =IF($A$19,"n.a.",SUM(D27:M27)) -> 0
A28: Discretionary outlaysb | B28: n.a. | C28: =IF($A$19,"n.a.",0) -> 0 | D28: =IF($A$19,"n.a.",0) -> 0 | E28: =IF($A$19,"n.a.",0) -> 0 | F28: =IF($A$19,"n.a.",0) -> 0 | G28: =IF($A$19,"n.a.",0) -> 0 | H28: =IF($A$19,"n.a.",0) -> 0 | I28: =IF($A$19,"n.a.",0) -> 0 | J28: =IF($A$19,"n.a.",0) -> 0 | ... M28: =IF($A$19,"n.a.",0) -> 0 | N28: =IF($A$19,"n.a.",SUM(D28:H28)) -> 0 | O28: =IF($A$19,"n.a.",SUM(D28:M28)) -> 0
A29: Net interest outlays
A30: Effects from changes in interest rates | B30: n.a. | C30: {=IF($A$19,"n.a.",ROUND(SUMPRODUCT(TRANSPOSE($C122:$M122),C124:C134),3)+ROUND(C136*C122/('7. Interest Rates_CBO'!C63-'7. Interest Rates_CBO'!C62),3))} -> 5.219 | D30: {=IF($A$19,"n.a.",ROUND(SUMPRODUCT(TRANSPOSE($C122:$M122),D124:D134),3)+ROUND(D136*D122/('7. Interest Rates_CBO'!D63-'7. Interest Rates_CBO'!D62),3))} -> 12.742 | E30: {=IF($A$19,"n.a.",ROUND(SUMPRODUCT(TRANSPOSE($C122:$M122),E124:E134),3)+ROUND(E136*E122/('7. Interest Rates_CBO'!E63-'7. Interest Rates_CBO'!E62),3))} -> 17.446 | F30: {=IF($A$19,"n.a.",ROUND(SUMPRODUCT(TRANSPOSE($C122:$M122),F124:F134),3)+ROUND(F136*F122/('7. Interest Rates_CBO'!F63-'7. Interest Rates_CBO'!F62),3))} -> 21.701 | G30: {=IF($A$19,"n.a.",ROUND(SUMPRODUCT(TRANSPOSE($C122:$M122),G124:G134),3)+ROUND(G136*G122/('7. Interest Rates_CBO'!G63-'7. Interest Rates_CBO'!G62),3))} -> 25.642 | H30: {=IF($A$19,"n.a.",ROUND(SUMPRODUCT(TRANSPOSE($C122:$M122),H124:H134),3)+ROUND(H136*H122/('7. Interest Rates_CBO'!H63-'7. Interest Rates_CBO'!H62),3))} -> 29.476 | I30: {=IF($A$19,"n.a.",ROUND(SUMPRODUCT(TRANSPOSE($C122:$M122),I124:I134),3)+ROUND(I136*I122/('7. Interest Rates_CBO'!I63-'7. Interest Rates_CBO'!I62),3))} -> 32.842 | J30: {=IF($A$19,"n.a.",ROUND(SUMPRODUCT(TRANSPOSE($C122:$M122),J124:J134),3)+ROUND(J136*J122/('7. Interest Rates_CBO'!J63-'7. Interest Rates_CBO'!J62),3))} -> 36.317 | ... M30: {=IF($A$19,"n.a.",ROUND(SUMPRODUCT(TRANSPOSE($C122:$M122),M124:M134),3)+ROUND(M136*M122/('7. Interest Rates_CBO'!M63-'7. Interest Rates_CBO'!M62),3))} -> 45.526 | N30: =IF($A$19,"n.a.",SUM(D30:H30)) -> 107.007 | O30: =IF($A$19,"n.a.",SUM(D30:M30)) -> 303.656
A31: Debt service | B31: n.a. | C31: {=IF($A$19,"n.a.",ROUND(SUMPRODUCT($C138:$M138,TRANSPOSE(C140:C150)),3) + ROUND((-C152)*C138/('7. Interest Rates_CBO'!C24+'7. Interest Rates_CBO'!C18),3))} -> 0.083 | D31: {=IF($A$19,"n.a.",ROUND(SUMPRODUCT($C138:$M138,TRANSPOSE(D140:D150)),3) + ROUND((-D152)*D138/('7. Interest Rates_CBO'!D24+'7. Interest Rates_CBO'!D18),3))} -> 0.593 | E31: {=IF($A$19,"n.a.",ROUND(SUMPRODUCT($C138:$M138,TRANSPOSE(E140:E150)),3) + ROUND((-E152)*E138/('7. Interest Rates_CBO'!E24+'7. Interest Rates_CBO'!E18),3))} -> 1.239 | F31: {=IF($A$19,"n.a.",ROUND(SUMPRODUCT($C138:$M138,TRANSPOSE(F140:F150)),3) + ROUND((-F152)*F138/('7. Interest Rates_CBO'!F24+'7. Interest Rates_CBO'!F18),3))} -> 2.035 | G31: {=IF($A$19,"n.a.",ROUND(SUMPRODUCT($C138:$M138,TRANSPOSE(G140:G150)),3) + ROUND((-G152)*G138/('7. Interest Rates_CBO'!G24+'7. Interest Rates_CBO'!G18),3))} -> 2.966 | H31: {=IF($A$19,"n.a.",ROUND(SUMPRODUCT($C138:$M138,TRANSPOSE(H140:H150)),3) + ROUND((-H152)*H138/('7. Interest Rates_CBO'!H24+'7. Interest Rates_CBO'!H18),3))} -> 4.043 | I31: {=IF($A$19,"n.a.",ROUND(SUMPRODUCT($C138:$M138,TRANSPOSE(I140:I150)),3) + ROUND((-I152)*I138/('7. Interest Rates_CBO'!I24+'7. Interest Rates_CBO'!I18),3))} -> 5.24 | J31: {=IF($A$19,"n.a.",ROUND(SUMPRODUCT($C138:$M138,TRANSPOSE(J140:J150)),3) + ROUND((-J152)*J138/('7. Interest Rates_CBO'!J24+'7. Interest Rates_CBO'!J18),3))} -> 6.579 | ... M31: {=IF($A$19,"n.a.",ROUND(SUMPRODUCT($C138:$M138,TRANSPOSE(M140:M150)),3) + ROUND((-M152)*M138/('7. Interest Rates_CBO'!M24+'7. Interest Rates_CBO'!M18),3))} -> 11.428 | N31: =IF($A$19,"n.a.",SUM(D31:H31)) -> 10.876 | O31: =IF($A$19,"n.a.",SUM(D31:M31)) -> 51.833
B32: ____ | C32: ____ | D32: ____ | E32: ____ | F32: ____ | G32: ____ | H32: ____ | I32: ____ | J32: ____ | K32: ____ | L32: ____ | M32: ____ | N32: ____ | O32: ____
A33: Subtotal, net interest outlays | B33: n.a. | C33: =IF($A$19,"n.a.",C30+C31) -> 5.302 | D33: =IF($A$19,"n.a.",D30+D31) -> 13.335 | E33: =IF($A$19,"n.a.",E30+E31) -> 18.685 | F33: =IF($A$19,"n.a.",F30+F31) -> 23.736 | G33: =IF($A$19,"n.a.",G30+G31) -> 28.608 | H33: =IF($A$19,"n.a.",H30+H31) -> 33.519 | I33: =IF($A$19,"n.a.",I30+I31) -> 38.082 | J33: =IF($A$19,"n.a.",J30+J31) -> 42.896 | ... M33: =IF($A$19,"n.a.",M30+M31) -> 56.954 | N33: =IF($A$19,"n.a.",SUM(D33:H33)) -> 117.883 | O33: =IF($A$19,"n.a.",SUM(D33:M33)) -> 355.489
A35: Total change in outlays | B35: n.a. | C35: =IF($A$19,"n.a.",C27+C28+C33) -> 5.302 | D35: =IF($A$19,"n.a.",D27+D28+D33) -> 13.335 | E35: =IF($A$19,"n.a.",E27+E28+E33) -> 18.685 | F35: =IF($A$19,"n.a.",F27+F28+F33) -> 23.736 | G35: =IF($A$19,"n.a.",G27+G28+G33) -> 28.608 | H35: =IF($A$19,"n.a.",H27+H28+H33) -> 33.519 | I35: =IF($A$19,"n.a.",I27+I28+I33) -> 38.082 | J35: =IF($A$19,"n.a.",J27+J28+J33) -> 42.896 | ... M35: =IF($A$19,"n.a.",M27+M28+M33) -> 56.954 | N35: =IF($A$19,"n.a.",SUM(D35:H35)) -> 117.883 | O35: =IF($A$19,"n.a.",SUM(D35:M35)) -> 355.489
A37: Increase (-) or decrease in the deficit relative to CBO's baseline | B37: n.a. | C37: =IF($A$19,"n.a.",C24-C35) -> -7.865 | D37: =IF($A$19,"n.a.",D24-D35) -> -15.9 | E37: =IF($A$19,"n.a.",E24-E35) -> -20.363 | F37: =IF($A$19,"n.a.",F24-F35) -> -24.616 | G37: =IF($A$19,"n.a.",G24-G35) -> -28.781 | H37: =IF($A$19,"n.a.",H24-H35) -> -33.019 | I37: =IF($A$19,"n.a.",I24-I35) -> -37.071 | J37: =IF($A$19,"n.a.",J24-J35) -> -41.383 | ... M37: =IF($A$19,"n.a.",M24-M35) -> -54.319 | N37: =IF($A$19,"n.a.",SUM(D37:H37)) -> -122.679 | O37: =IF($A$19,"n.a.",SUM(D37:M37)) -> -350.904
A39: Deficit (-) or surplus
A40: January 2025 baseline | B40: -1832.381 | C40: -1865.251 | D40: -1713.258 | E40: -1686.942 | F40: -1910.776 | G40: -1938.268 | H40: -2139.721 | I40: -2232.786 | J40: -2370.582 | K40: -2637.299 | L40: -2597.25 | M40: -2531.378 | N40: -9388.965 | O40: -21758.26
A41: User-specified scenario | B41: =IF($A$19,"n.a.",B40) -> -1832.381 | C41: =IF($A$19,"n.a.",C40+C37) -> -1873.116 | D41: =IF($A$19,"n.a.",D40+D37) -> -1729.158 | E41: =IF($A$19,"n.a.",E40+E37) -> -1707.305 | F41: =IF($A$19,"n.a.",F40+F37) -> -1935.392 | G41: =IF($A$19,"n.a.",G40+G37) -> -1967.049 | H41: =IF($A$19,"n.a.",H40+H37) -> -2172.74 | I41: =IF($A$19,"n.a.",I40+I37) -> -2269.857 | J41: =IF($A$19,"n.a.",J40+J37) -> -2411.965 | ... M41: =IF($A$19,"n.a.",M40+M37) -> -2585.697 | N41: =IF($A$19,"n.a.",SUM(D41:H41)) -> -9511.644 | O41: =IF($A$19,"n.a.",SUM(D41:M41)) -> -22109.164
A43: Debt held by the public
A44: January 2025 baseline | B44: 28199.313 | C44: 30102.749 | D44: 31882.633 | E44: 33636.105 | F44: 35600.64 | G44: 37580.5 | H44: 39747.651 | I44: 41992.385 | J44: 44371.755 | K44: 46985.029 | L44: 49555.504 | M44: 52055.866 | N44: n.a. | O44: n.a.
A45: User-specified scenario | B45: =IF($A$19,"n.a.",B44) -> 28199.313 | C45: =IF($A$19,"n.a.",C44-SUM($C37:C37)) -> 30110.614 | D45: =IF($A$19,"n.a.",D44-SUM($C37:D37)) -> 31906.398 | E45: =IF($A$19,"n.a.",E44-SUM($C37:E37)) -> 33680.233 | F45: =IF($A$19,"n.a.",F44-SUM($C37:F37)) -> 35669.384 | G45: =IF($A$19,"n.a.",G44-SUM($C37:G37)) -> 37678.025 | H45: =IF($A$19,"n.a.",H44-SUM($C37:H37)) -> 39878.195 | I45: =IF($A$19,"n.a.",I44-SUM($C37:I37)) -> 42160 | J45: =IF($A$19,"n.a.",J44-SUM($C37:J37)) -> 44580.753 | ... M45: =IF($A$19,"n.a.",M44-SUM($C37:M37)) -> 52414.635 | N45: n.a. | O45: n.a.
A47: Deficit (-) or surplus (percentage of GDP)
A48: January 2025 baseline | B48: -6.3562158 | C48: -6.1894147 | D48: -5.4664504 | E48: -5.184518 | F48: -5.659123 | G48: -5.5304586 | H48: -5.8793652 | I48: -5.9080768 | J48: -6.0393242 | K48: -6.4690633 | L48: -6.1356563 | M48: -5.7614482 | N48: -5.5528141 | O48: -5.830748
A49: User-specified scenario | B49: =IF($A$19,"n.a.",B48) -> -6.3562158 | C49: =IF($A$19,"n.a.",ROUND(C41/C70*100,3)) -> -6.216 | D49: =IF($A$19,"n.a.",ROUND(D41/D70*100,3)) -> -5.517 | E49: =IF($A$19,"n.a.",ROUND(E41/E70*100,3)) -> -5.247 | F49: =IF($A$19,"n.a.",ROUND(F41/F70*100,3)) -> -5.732 | G49: =IF($A$19,"n.a.",ROUND(G41/G70*100,3)) -> -5.613 | H49: =IF($A$19,"n.a.",ROUND(H41/H70*100,3)) -> -5.97 | I49: =IF($A$19,"n.a.",ROUND(I41/I70*100,3)) -> -6.006 | J49: =IF($A$19,"n.a.",ROUND(J41/J70*100,3)) -> -6.145 | ... M49: =IF($A$19,"n.a.",ROUND(M41/M70*100,3)) -> -5.885 | N49: =IF($A$19,"n.a.",ROUND(SUM(D41:H41)/SUM(D70:H70)*100,3)) -> -5.625 | O49: =IF($A$19,"n.a.",ROUND(SUM(D41:M41)/SUM(D70:M70)*100,3)) -> -5.925
A51: Debt held by the public (percentage of GDP)
A52: January 2025 baseline | B52: 97.818585 | C52: 99.889183 | D52: 101.72714 | E52: 103.37462 | F52: 105.438 | G52: 107.22841 | H52: 109.21562 | I52: 111.1142 | J52: 113.04204 | K52: 115.25016 | L52: 117.06826 | M52: 118.47981 | N52: n.a. | O52: n.a.
A53: User-specified scenario | B53: =IF($A$19,"n.a.",B52) -> 97.818585 | C53: =IF($A$19,"n.a.",ROUND(C45/C70*100,3)) -> 99.915 | D53: =IF($A$19,"n.a.",ROUND(D45/D70*100,3)) -> 101.803 | E53: =IF($A$19,"n.a.",ROUND(E45/E70*100,3)) -> 103.51 | F53: =IF($A$19,"n.a.",ROUND(F45/F70*100,3)) -> 105.642 | G53: =IF($A$19,"n.a.",ROUND(G45/G70*100,3)) -> 107.507 | H53: =IF($A$19,"n.a.",ROUND(H45/H70*100,3)) -> 109.574 | I53: =IF($A$19,"n.a.",ROUND(I45/I70*100,3)) -> 111.558 | J53: =IF($A$19,"n.a.",ROUND(J45/J70*100,3)) -> 113.575 | ... M53: =IF($A$19,"n.a.",ROUND(M45/M70*100,3)) -> 119.296 | N53: n.a. | O53: n.a.
B56: Economic indicators in CBO’s January 2025 baseline and under the user-specified scenario
...

Sheet 4. Inflation and Interest
A1: This workbook supplements CBO’s report How Changes in Economic Conditions Might Affect the Federal Budget: 2025 to 2035.
A2: www.cbo.gov/publication/61198
A5: To create an alternative scenario for inflation and interest rates, enter values between -1.0 percentage point and 1.0 percentage point in each of the green cells. (Only the green cells can be edited; all other cells are locked. Values outside of the specified range will produce errors.) The change in budgetary outcomes relative to those in CBO’s baseline will be calculated and appear automatically. Values for key economic indicators are shown below those budgetary effects.
A7: 4. Interactive Table: How Changes in Inflation and Interest Rates Might Affect the Federal Budget
B9: 2024 | C9: 2025 | D9: 2026 | E9: 2027 | F9: 2028 | G9: 2029 | H9: 2030 | I9: 2031 | J9: 2032 | K9: 2033 | L9: 2034 | M9: 2035
C11: User-specified scenario for inflation and interest rates
O12: These initial values are the same as those used to generate the illustrative scenario shown in Worksheet 8, “Inflation and Interest_CBO.”
A13: Increase or decrease (-) in inflation relative to CBO’s January 2025 baseline (percentage points) | B13: n.a. | C13: 0.1 | D13: 0.1 | E13: 0.1 | F13: 0.1 | G13: 0.1 | H13: 0.1 | I13: 0.1 | J13: 0.1 | K13: 0.1 | L13: 0.1 | M13: 0.1
A14: Increase or decrease (-) in interest rates relative to CBO’s January 2025 baseline (percentage points) | B14: n.a. | C14: 0.1 | D14: 0.1 | E14: 0.1 | F14: 0.1 | G14: 0.1 | H14: 0.1 | I14: 0.1 | J14: 0.1 | K14: 0.1 | L14: 0.1 | M14: 0.1
A15: =IF($A$22,"Please keep values in the range [-1.0, 1.0] percentage point per year.","")
A16: Inflation (percent)a
A17: January 2025 baseline | B17: 2.413 | C17: 2.198 | D17: 2.075 | E17: 1.995 | F17: 1.988 | G17: 1.992 | H17: 1.987 | I17: 1.986 | J17: 1.987 | K17: 1.991 | L17: 1.989 | M17: 1.99
A18: User-specified scenario | B18: =IF($A$23,"n.a.",B17) -> 2.413 | C18: =IF($A$23,"n.a.",C17+C13) -> 2.298 | D18: =IF($A$23,"n.a.",D17+D13) -> 2.175 | E18: =IF($A$23,"n.a.",E17+E13) -> 2.095 | F18: =IF($A$23,"n.a.",F17+F13) -> 2.088 | G18: =IF($A$23,"n.a.",G17+G13) -> 2.092 | H18: =IF($A$23,"n.a.",H17+H13) -> 2.087 | I18: =IF($A$23,"n.a.",I17+I13) -> 2.086 | J18: =IF($A$23,"n.a.",J17+J13) -> 2.087 | ... M18: =IF($A$23,"n.a.",M17+M13) -> 2.09
A19: Interest rate on 10-year Treasury notes (percent)b
A20: January 2025 baseline | B20: 4.188 | C20: 4.093 | D20: 3.935 | E20: 3.914 | F20: 3.894 | G20: 3.871 | H20: 3.85 | I20: 3.836 | J20: 3.826 | K20: 3.815 | L20: 3.797 | M20: 3.772
A21: User-specified scenario | B21: =IF($A$23,"n.a.",B20) -> 4.188 | C21: =IF($A$23,"n.a.",C20+C14) -> 4.193 | D21: =IF($A$23,"n.a.",D20+D14) -> 4.035 | E21: =IF($A$23,"n.a.",E20+E14) -> 4.014 | F21: =IF($A$23,"n.a.",F20+F14) -> 3.994 | G21: =IF($A$23,"n.a.",G20+G14) -> 3.971 | H21: =IF($A$23,"n.a.",H20+H14) -> 3.95 | I21: =IF($A$23,"n.a.",I20+I14) -> 3.936 | J21: =IF($A$23,"n.a.",J20+J14) -> 3.926 | ... M21: =IF($A$23,"n.a.",M20+M14) -> 3.872
A23: =IF(OR(MAX(C13:M14)>1,MIN(C13:M14)<-1),1,0) -> 0
C25: Budgetary effects (billions of dollars) | N25: Total
N26: 2026- | O26: 2026-
B27: 2024 | C27: 2025 | D27: 2026 | E27: 2027 | F27: 2028 | G27: 2029 | H27: 2030 | I27: 2031 | J27: 2032 | K27: 2033 | L27: 2034 | M27: 2035 | N27: 2030 | O27: 2035
A28: Changes in revenues | B28: n.a. | C28: {=IF($A$23,"n.a.",ROUND(TRUNC(SUMPRODUCT($C14:$M14,TRANSPOSE(C113:C123))-C125*(C14*0.75),3)+('8. Inflation and Interest_CBO'!C11-'7. Interest Rates_CBO'!C11)/('8. Inflation and Interest_CBO'!C58-'8. Inflation and Interest_CBO'!C57)*(ROUND('4. Inflation and Interest'!C75,1)-ROUND('4. Inflation and Interest'!C74,1)),3))} -> 1.559 | D28: {=IF($A$23,"n.a.",ROUND(TRUNC(SUMPRODUCT($C14:$M14,TRANSPOSE(D113:D123))-D125*(D14*0.75+C14*0.25),3)+('8. Inflation and Interest_CBO'!D11-'7. Interest Rates_CBO'!D11)/('8. Inflation and Interest_CBO'!D58-'8. Inflation and Interest_CBO'!D57)*(ROUND('4. Inflation and Interest'!D75,1)-ROUND('4. Inflation and Interest'!D74,1)),3))} -> 7.261 | E28: {=IF($A$23,"n.a.",ROUND(TRUNC(SUMPRODUCT($C14:$M14,TRANSPOSE(E113:E123))-E125*(E14*0.75+D14*0.25),3)+('8. Inflation and Interest_CBO'!E11-'7. Interest Rates_CBO'!E11)/('8. Inflation and Interest_CBO'!E58-'8. Inflation and Interest_CBO'!E57)*(ROUND('4. Inflation and Interest'!E75,1)-ROUND('4. Inflation and Interest'!E74,1)),3))} -> 13.503 | F28: {=IF($A$23,"n.a.",ROUND(TRUNC(SUMPRODUCT($C14:$M14,TRANSPOSE(F113:F123))-F125*(F14*0.75+E14*0.25),3)+('8. Inflation and Interest_CBO'!F11-'7. Interest Rates_CBO'!F11)/('8. Inflation and Interest_CBO'!F58-'8. Inflation and Interest_CBO'!F57)*(ROUND('4. Inflation and Interest'!F75,1)-ROUND('4. Inflation and Interest'!F74,1)),3))} -> 19.902 | G28: {=IF($A$23,"n.a.",ROUND(TRUNC(SUMPRODUCT($C14:$M14,TRANSPOSE(G113:G123))-G125*(G14*0.75+F14*0.25),3)+('8. Inflation and Interest_CBO'!G11-'7. Interest Rates_CBO'!G11)/('8. Inflation and Interest_CBO'!G58-'8. Inflation and Interest_CBO'!G57)*(ROUND('4. Inflation and Interest'!G75,1)-ROUND('4. Inflation and Interest'!G74,1)),3))} -> 26.691 | H28: {=IF($A$23,"n.a.",ROUND(TRUNC(SUMPRODUCT($C14:$M14,TRANSPOSE(H113:H123))-H125*(H14*0.75+G14*0.25),3)+('8. Inflation and Interest_CBO'!H11-'7. Interest Rates_CBO'!H11)/('8. Inflation and Interest_CBO'!H58-'8. Inflation and Interest_CBO'!H57)*(ROUND('4. Inflation and Interest'!H75,1)-ROUND('4. Inflation and Interest'!H74,1)),3))} -> 33.925 | I28: {=IF($A$23,"n.a.",ROUND(TRUNC(SUMPRODUCT($C14:$M14,TRANSPOSE(I113:I123))-I125*(I14*0.75+H14*0.25),3)+('8. Inflation and Interest_CBO'!I11-'7. Interest Rates_CBO'!I11)/('8. Inflation and Interest_CBO'!I58-'8. Inflation and Interest_CBO'!I57)*(ROUND('4. Inflation and Interest'!I75,1)-ROUND('4. Inflation and Interest'!I74,1)),3))} -> 41.556 | J28: {=IF($A$23,"n.a.",ROUND(TRUNC(SUMPRODUCT($C14:$M14,TRANSPOSE(J113:J123))-J125*(J14*0.75+I14*0.25),3)+('8. Inflation and Interest_CBO'!J11-'7. Interest Rates_CBO'!J11)/('8. Inflation and Interest_CBO'!J58-'8. Inflation and Interest_CBO'!J57)*(ROUND('4. Inflation and Interest'!J75,1)-ROUND('4. Inflation and Interest'!J74,1)),3))} -> 49.813 | K28: {=IF($A$23,"n.a.",ROUND(TRUNC(SUMPRODUCT($C14:$M14,TRANSPOSE(K113:K123))-K125*(K14*0.75+J14*0.25),3)+('8. Inflation and Interest_CBO'!K11-'7. Interest Rates_CBO'!K11)/('8. Inflation and Interest_CBO'!K58-'8. Inflation and Interest_CBO'!K57)*(ROUND('4. Inflation and Interest'!K75,1)-ROUND('4. Inflation and Interest'!K74,1)),3))} -> 58.187 | ... M28: {=IF($A$23,"n.a.",ROUND(TRUNC(SUMPRODUCT($C14:$M14,TRANSPOSE(M113:M123))-M125*(M14*0.75+L14*0.25),3)+('8. Inflation and Interest_CBO'!M11-'7. Interest Rates_CBO'!M11)/('8. Inflation and Interest_CBO'!M58-'8. Inflation and Interest_CBO'!M57)*(ROUND('4. Inflation and Interest'!M75,1)-ROUND('4. Inflation and Interest'!M74,1)),3))} -> 77.183 | N28: =IF($A$23,"n.a.",SUM(D28:H28)) -> 101.282 | O28: =IF($A$23,"n.a.",SUM(D28:M28)) -> 395.472
A30: Changes in outlays
A31: Mandatory outlays | B31: n.a. | C31: =IF($A$23,"n.a.",ROUND('7. Interest Rates_CBO'!C14*C127/('7. Interest Rates_CBO'!C63-'7. Interest Rates_CBO'!C62)+('8. Inflation and Interest_CBO'!C14-'7. Interest Rates_CBO'!C14)/('8. Inflation and Interest_CBO'!C58-'8. Inflation and Interest_CBO'!C57)*(ROUND('4. Inflation and Interest'!C75,1)-ROUND('4. Inflation and Interest'!C74,1)),3)) -> 0.403 | D31: =IF($A$23,"n.a.",ROUND('7. Interest Rates_CBO'!D14*D127/('7. Interest Rates_CBO'!D63-'7. Interest Rates_CBO'!D62)+('8. Inflation and Interest_CBO'!D14-'7. Interest Rates_CBO'!D14)/('8. Inflation and Interest_CBO'!D58-'8. Inflation and Interest_CBO'!D57)*(ROUND('4. Inflation and Interest'!D75,1)-ROUND('4. Inflation and Interest'!D74,1)),3)) -> 3.296 | E31: =IF($A$23,"n.a.",ROUND('7. Interest Rates_CBO'!E14*E127/('7. Interest Rates_CBO'!E63-'7. Interest Rates_CBO'!E62)+('8. Inflation and Interest_CBO'!E14-'7. Interest Rates_CBO'!E14)/('8. Inflation and Interest_CBO'!E58-'8. Inflation and Interest_CBO'!E57)*(ROUND('4. Inflation and Interest'!E75,1)-ROUND('4. Inflation and Interest'!E74,1)),3)) -> 7.126 | F31: =IF($A$23,"n.a.",ROUND('7. Interest Rates_CBO'!F14*F127/('7. Interest Rates_CBO'!F63-'7. Interest Rates_CBO'!F62)+('8. Inflation and Interest_CBO'!F14-'7. Interest Rates_CBO'!F14)/('8. Inflation and Interest_CBO'!F58-'8. Inflation and Interest_CBO'!F57)*(ROUND('4. Inflation and Interest'!F75,1)-ROUND('4. Inflation and Interest'!F74,1)),3)) -> 11.473 | G31: =IF($A$23,"n.a.",ROUND('7. Interest Rates_CBO'!G14*G127/('7. Interest Rates_CBO'!G63-'7. Interest Rates_CBO'!G62)+('8. Inflation and Interest_CBO'!G14-'7. Interest Rates_CBO'!G14)/('8. Inflation and Interest_CBO'!G58-'8. Inflation and Interest_CBO'!G57)*(ROUND('4. Inflation and Interest'!G75,1)-ROUND('4. Inflation and Interest'!G74,1)),3)) -> 16.016 | H31: =IF($A$23,"n.a.",ROUND('7. Interest Rates_CBO'!H14*H127/('7. Interest Rates_CBO'!H63-'7. Interest Rates_CBO'!H62)+('8. Inflation and Interest_CBO'!H14-'7. Interest Rates_CBO'!H14)/('8. Inflation and Interest_CBO'!H58-'8. Inflation and Interest_CBO'!H57)*(ROUND('4. Inflation and Interest'!H75,1)-ROUND('4. Inflation and Interest'!H74,1)),3)) -> 21.023 | I31: =IF($A$23,"n.a.",ROUND('7. Interest Rates_CBO'!I14*I127/('7. Interest Rates_CBO'!I63-'7. Interest Rates_CBO'!I62)+('8. Inflation and Interest_CBO'!I14-'7. Interest Rates_CBO'!I14)/('8. Inflation and Interest_CBO'!I58-'8. Inflation and Interest_CBO'!I57)*(ROUND('4. Inflation and Interest'!I75,1)-ROUND('4. Inflation and Interest'!I74,1)),3)) -> 26.272 | J31: =IF($A$23,"n.a.",ROUND('7. Interest Rates_CBO'!J14*J127/('7. Interest Rates_CBO'!J63-'7. Interest Rates_CBO'!J62)+('8. Inflation and Interest_CBO'!J14-'7. Interest Rates_CBO'!J14)/('8. Inflation and Interest_CBO'!J58-'8. Inflation and Interest_CBO'!J57)*(ROUND('4. Inflation and Interest'!J75,1)-ROUND('4. Inflation and Interest'!J74,1)),3)) -> 32.243 | ... M31: =IF($A$23,"n.a.",ROUND('7. Interest Rates_CBO'!M14*M127/('7. Interest Rates_CBO'!M63-'7. Interest Rates_CBO'!M62)+('8. Inflation and Interest_CBO'!M14-'7. Interest Rates_CBO'!M14)/('8. Inflation and Interest_CBO'!M58-'8. Inflation and Interest_CBO'!M57)*(ROUND('4. Inflation and Interest'!M75,1)-ROUND('4. Inflation and Interest'!M74,1)),3)) -> 51.832 | N31: =IF($A$23,"n.a.",SUM(D31:H31)) -> 58.934 | O31: =IF($A$23,"n.a.",SUM(D31:M31)) -> 253.657
A32: Discretionary outlays | B32: n.a. | C32: =IF($A$23,"n.a.",'8. Inflation and Interest_CBO'!C15/('8. Inflation and Interest_CBO'!C58-'8. Inflation and Interest_CBO'!C57)*(ROUND('4. Inflation and Interest'!C75,1)-ROUND('4. Inflation and Interest'!C74,1))) -> 0 | D32: =IF($A$23,"n.a.",'8. Inflation and Interest_CBO'!D15/('8. Inflation and Interest_CBO'!D58-'8. Inflation and Interest_CBO'!D57)*(ROUND('4. Inflation and Interest'!D75,1)-ROUND('4. Inflation and Interest'!D74,1))) -> 1.088 | E32: =IF($A$23,"n.a.",'8. Inflation and Interest_CBO'!E15/('8. Inflation and Interest_CBO'!E58-'8. Inflation and Interest_CBO'!E57)*(ROUND('4. Inflation and Interest'!E75,1)-ROUND('4. Inflation and Interest'!E74,1))) -> 2.665 | F32: =IF($A$23,"n.a.",'8. Inflation and Interest_CBO'!F15/('8. Inflation and Interest_CBO'!F58-'8. Inflation and Interest_CBO'!F57)*(ROUND('4. Inflation and Interest'!F75,1)-ROUND('4. Inflation and Interest'!F74,1))) -> 4.464 | G32: =IF($A$23,"n.a.",'8. Inflation and Interest_CBO'!G15/('8. Inflation and Interest_CBO'!G58-'8. Inflation and Interest_CBO'!G57)*(ROUND('4. Inflation and Interest'!G75,1)-ROUND('4. Inflation and Interest'!G74,1))) -> 6.421 | H32: =IF($A$23,"n.a.",'8. Inflation and Interest_CBO'!H15/('8. Inflation and Interest_CBO'!H58-'8. Inflation and Interest_CBO'!H57)*(ROUND('4. Inflation and Interest'!H75,1)-ROUND('4. Inflation and Interest'!H74,1))) -> 8.545 | I32: =IF($A$23,"n.a.",'8. Inflation and Interest_CBO'!I15/('8. Inflation and Interest_CBO'!I58-'8. Inflation and Interest_CBO'!I57)*(ROUND('4. Inflation and Interest'!I75,1)-ROUND('4. Inflation and Interest'!I74,1))) -> 10.748 | J32: =IF($A$23,"n.a.",'8. Inflation and Interest_CBO'!J15/('8. Inflation and Interest_CBO'!J58-'8. Inflation and Interest_CBO'!J57)*(ROUND('4. Inflation and Interest'!J75,1)-ROUND('4. Inflation and Interest'!J74,1))) -> 13.046 | ... M32: =IF($A$23,"n.a.",'8. Inflation and Interest_CBO'!M15/('8. Inflation and Interest_CBO'!M58-'8. Inflation and Interest_CBO'!M57)*(ROUND('4. Inflation and Interest'!M75,1)-ROUND('4. Inflation and Interest'!M74,1))) -> 20.545 | N32: =IF($A$23,"n.a.",SUM(D32:H32)) -> 23.183 | O32: =IF($A$23,"n.a.",SUM(D32:M32)) -> 100.904
A33: Net interest outlays
